<mujoco model="simple">
  <compiler angle="radian" autolimits="true"/>
  <default>
        <joint type="hinge" frictionloss="0.1" damping='2' />
        <position ctrllimited="true" ctrlrange="-3.14 3.14" forcelimited="true" forcerange="-50 50" kp="10" />
  </default>
  <asset>
    <texture name="grid" type="2d" builtin="checker" rgb1=".9 .8 .7" rgb2=".4 .4 .4" width="300" height="300" mark="edge" markrgb=".2 .3 .4"/>
    <material name="grid" texture="grid" texrepeat="2 2" texuniform="true" reflectance=".2"/>
  </asset>

  <worldbody>
    <light directional='true' diffuse='.3 .3 .3' specular='0.3 0.3 0.3' pos='0.3 0.3 3' dir='0.2 0.2 -1'/>
    <light castshadow="false" directional='true' diffuse='.3 .3 .3' specular='0.3 0.3 0.3' pos='0 0 3' dir='-1 1 -1'/>
    <light castshadow="false" directional='true' diffuse='.3 .3 .3' specular='0.3 0.3 0.3' pos='0 1 3' dir='0 -1 -1'/>
    <geom name="ground" type="plane" pos="0 0 0" size="10 10 0.1" material="grid" solimp=".9 .95 .001" solref='-10000 -1000'/>
    <camera name="closeup" pos="0 -.1 .07" xyaxes="3 0 0 0 1 2"/>
    <body name="a0" pos="0 0 0">
      <joint name="j1" axis='0 0 1' range="-10000 10000"/>
      <geom pos="0.2 0 0" size="0.2 0.025 0.01" type="box" contype="0" conaffinity="0" rgba="0.2 0.2 0.8 1" />
      <body name="a1" pos="0.4 0 0">
        <joint name="j2" axis='0 0 1'/>
        <site name="s1" pos="0 0 0"/>
        <geom pos="0.5 0 0" size="0.5 0.025 0.01" type="box" contype="0" conaffinity="0" rgba="0.2 0.8 0.2 1" />
      </body>
    </body>

    <body name="b1" pos="1.4 0 0">
      <geom pos="0 0 0" size="0.01 0.7" euler="0 1.5708 0" type="cylinder" contype="0" conaffinity="0" rgba="0.2 0.2 0.8 1" />
      <body name="b2" pos="0 0 0">
        <joint name="j3" axis='1 0 0' type='slide' range="-1000 1000"/>
        <site name="s2" pos="0 0 0"/>
        <geom name="bb2" pos="0 0 0" size="0.025 0.025 0.01" type="box" contype="0" conaffinity="0" rgba="0.8 0.2 0.2 1" />
      </body>
    </body>

  </worldbody>
  <contact>
        <exclude name="e0" body1="a0" body2="a1" />
        <exclude name="e3" body1="a0" body2="b1" />
        <exclude name="e4" body1="a0" body2="b2" />
        <exclude name="e1" body1="a1" body2="b1" />
        <exclude name="e2" body1="b1" body2="b2" />
  </contact>
  <equality>
    <connect name="lc" body1="b2" body2="a1" anchor="0 0 0"/>
  </equality>

  <sensor>
    <actuatorfrc name="s_pj1" actuator="pj1" />
    <force  name="s_j1" site="s1" />
    <force  name="s_j2" site="s2" />
  </sensor>

  <actuator>
    <!-- <position name='pj1' joint='j1' kp="10" ctrlrange="-100000 100000"/ dampratio="0.8"> -->
    <velocity name='pj1' joint='j1'  ctrllimited="true" ctrlrange="-1000 1000"/>
    <!--<general name='pj3' joint='j3' ctrlrange="-10 10"/>-->
  </actuator>


</mujoco>
